[2021-08-12 04:50:33,903] {taskinstance.py:896} INFO - Dependencies all met for <TaskInstance: pipeline_try.transform_data 2021-08-11T00:00:00+00:00 [queued]>
[2021-08-12 04:50:33,970] {taskinstance.py:896} INFO - Dependencies all met for <TaskInstance: pipeline_try.transform_data 2021-08-11T00:00:00+00:00 [queued]>
[2021-08-12 04:50:33,972] {taskinstance.py:1087} INFO - 
--------------------------------------------------------------------------------
[2021-08-12 04:50:33,975] {taskinstance.py:1088} INFO - Starting attempt 1 of 2
[2021-08-12 04:50:33,978] {taskinstance.py:1089} INFO - 
--------------------------------------------------------------------------------
[2021-08-12 04:50:34,059] {taskinstance.py:1107} INFO - Executing <Task(PythonOperator): transform_data> on 2021-08-11T00:00:00+00:00
[2021-08-12 04:50:34,095] {standard_task_runner.py:52} INFO - Started process 203 to run task
[2021-08-12 04:50:34,100] {standard_task_runner.py:76} INFO - Running: ['***', 'tasks', 'run', 'pipeline_try', 'transform_data', '2021-08-11T00:00:00+00:00', '--job-id', '16', '--pool', 'default_pool', '--raw', '--subdir', 'DAGS_FOLDER/pipeline_try1.py', '--cfg-path', '/tmp/tmp31l9fm55', '--error-file', '/tmp/tmpt6d45_la']
[2021-08-12 04:50:34,163] {standard_task_runner.py:77} INFO - Job 16: Subtask transform_data
[2021-08-12 04:50:34,474] {logging_mixin.py:104} INFO - Running <TaskInstance: pipeline_try.transform_data 2021-08-11T00:00:00+00:00 [running]> on host 9d72a0011461
[2021-08-12 04:50:34,804] {taskinstance.py:1302} INFO - Exporting the following env vars:
AIRFLOW_CTX_DAG_EMAIL=ameysonje242000@gmail.com
AIRFLOW_CTX_DAG_OWNER=amey
AIRFLOW_CTX_DAG_ID=pipeline_try
AIRFLOW_CTX_TASK_ID=transform_data
AIRFLOW_CTX_EXECUTION_DATE=2021-08-11T00:00:00+00:00
AIRFLOW_CTX_DAG_RUN_ID=scheduled__2021-08-11T00:00:00+00:00
[2021-08-12 04:50:34,847] {logging_mixin.py:104} INFO - C:\Users\amey sonje\Downloads\csv_data.csv
[2021-08-12 04:50:34,864] {logging_mixin.py:104} INFO - C:\Users\amey sonje\Downloads\csv_data_transformed.csv
[2021-08-12 04:50:34,885] {taskinstance.py:1501} ERROR - Task failed with exception
Traceback (most recent call last):
  File "/home/airflow/.local/lib/python3.6/site-packages/airflow/models/taskinstance.py", line 1157, in _run_raw_task
    self._prepare_and_execute_task_with_callbacks(context, task)
  File "/home/airflow/.local/lib/python3.6/site-packages/airflow/models/taskinstance.py", line 1331, in _prepare_and_execute_task_with_callbacks
    result = self._execute_task(context, task_copy)
  File "/home/airflow/.local/lib/python3.6/site-packages/airflow/models/taskinstance.py", line 1361, in _execute_task
    result = task_copy.execute(context=context)
  File "/home/airflow/.local/lib/python3.6/site-packages/airflow/operators/python.py", line 150, in execute
    return_value = self.execute_callable()
  File "/home/airflow/.local/lib/python3.6/site-packages/airflow/operators/python.py", line 161, in execute_callable
    return self.python_callable(*self.op_args, **self.op_kwargs)
  File "/opt/airflow/dags/pipeline_try1.py", line 31, in transform_data
    usecols=['Year','Industry_name_NZSIOC']
  File "/home/airflow/.local/lib/python3.6/site-packages/pandas/io/parsers.py", line 688, in read_csv
    return _read(filepath_or_buffer, kwds)
  File "/home/airflow/.local/lib/python3.6/site-packages/pandas/io/parsers.py", line 454, in _read
    parser = TextFileReader(fp_or_buf, **kwds)
  File "/home/airflow/.local/lib/python3.6/site-packages/pandas/io/parsers.py", line 948, in __init__
    self._make_engine(self.engine)
  File "/home/airflow/.local/lib/python3.6/site-packages/pandas/io/parsers.py", line 1180, in _make_engine
    self._engine = CParserWrapper(self.f, **self.options)
  File "/home/airflow/.local/lib/python3.6/site-packages/pandas/io/parsers.py", line 2010, in __init__
    self._reader = parsers.TextReader(src, **kwds)
  File "pandas/_libs/parsers.pyx", line 382, in pandas._libs.parsers.TextReader.__cinit__
  File "pandas/_libs/parsers.pyx", line 674, in pandas._libs.parsers.TextReader._setup_parser_source
FileNotFoundError: [Errno 2] No such file or directory: 'C:\\Users\\amey sonje\\Downloads\\csv_data.csv'
[2021-08-12 04:50:35,096] {taskinstance.py:1551} INFO - Marking task as UP_FOR_RETRY. dag_id=pipeline_try, task_id=transform_data, execution_date=20210811T000000, start_date=20210812T045033, end_date=20210812T045035
[2021-08-12 04:50:35,234] {local_task_job.py:149} INFO - Task exited with return code 1
[2021-08-12 06:14:03,819] {taskinstance.py:896} INFO - Dependencies all met for <TaskInstance: pipeline_try.transform_data 2021-08-11T00:00:00+00:00 [queued]>
[2021-08-12 06:14:03,837] {taskinstance.py:896} INFO - Dependencies all met for <TaskInstance: pipeline_try.transform_data 2021-08-11T00:00:00+00:00 [queued]>
[2021-08-12 06:14:03,837] {taskinstance.py:1087} INFO - 
--------------------------------------------------------------------------------
[2021-08-12 06:14:03,838] {taskinstance.py:1088} INFO - Starting attempt 1 of 2
[2021-08-12 06:14:03,838] {taskinstance.py:1089} INFO - 
--------------------------------------------------------------------------------
[2021-08-12 06:14:03,853] {taskinstance.py:1107} INFO - Executing <Task(PythonOperator): transform_data> on 2021-08-11T00:00:00+00:00
[2021-08-12 06:14:03,857] {standard_task_runner.py:52} INFO - Started process 740 to run task
[2021-08-12 06:14:03,864] {standard_task_runner.py:76} INFO - Running: ['***', 'tasks', 'run', 'pipeline_try', 'transform_data', '2021-08-11T00:00:00+00:00', '--job-id', '23', '--pool', 'default_pool', '--raw', '--subdir', 'DAGS_FOLDER/pipeline_try1.py', '--cfg-path', '/tmp/tmpstxkque7', '--error-file', '/tmp/tmpiunh_07e']
[2021-08-12 06:14:03,870] {standard_task_runner.py:77} INFO - Job 23: Subtask transform_data
[2021-08-12 06:14:03,927] {logging_mixin.py:104} INFO - Running <TaskInstance: pipeline_try.transform_data 2021-08-11T00:00:00+00:00 [running]> on host a84373444557
[2021-08-12 06:14:03,990] {taskinstance.py:1302} INFO - Exporting the following env vars:
AIRFLOW_CTX_DAG_EMAIL=ameysonje242000@gmail.com
AIRFLOW_CTX_DAG_OWNER=amey
AIRFLOW_CTX_DAG_ID=pipeline_try
AIRFLOW_CTX_TASK_ID=transform_data
AIRFLOW_CTX_EXECUTION_DATE=2021-08-11T00:00:00+00:00
AIRFLOW_CTX_DAG_RUN_ID=scheduled__2021-08-11T00:00:00+00:00
[2021-08-12 06:14:03,993] {logging_mixin.py:104} INFO - C:\Users\amey sonje\Downloads\csv_data.csv
[2021-08-12 06:14:03,993] {logging_mixin.py:104} INFO - C:\Users\amey sonje\Downloads\csv_data_transformed.csv
[2021-08-12 06:14:04,003] {taskinstance.py:1501} ERROR - Task failed with exception
Traceback (most recent call last):
  File "/home/airflow/.local/lib/python3.6/site-packages/airflow/models/taskinstance.py", line 1157, in _run_raw_task
    self._prepare_and_execute_task_with_callbacks(context, task)
  File "/home/airflow/.local/lib/python3.6/site-packages/airflow/models/taskinstance.py", line 1331, in _prepare_and_execute_task_with_callbacks
    result = self._execute_task(context, task_copy)
  File "/home/airflow/.local/lib/python3.6/site-packages/airflow/models/taskinstance.py", line 1361, in _execute_task
    result = task_copy.execute(context=context)
  File "/home/airflow/.local/lib/python3.6/site-packages/airflow/operators/python.py", line 150, in execute
    return_value = self.execute_callable()
  File "/home/airflow/.local/lib/python3.6/site-packages/airflow/operators/python.py", line 161, in execute_callable
    return self.python_callable(*self.op_args, **self.op_kwargs)
  File "/opt/airflow/dags/pipeline_try1.py", line 31, in transform_data
    usecols=['Year','Industry_name_NZSIOC']
  File "/home/airflow/.local/lib/python3.6/site-packages/pandas/io/parsers.py", line 688, in read_csv
    return _read(filepath_or_buffer, kwds)
  File "/home/airflow/.local/lib/python3.6/site-packages/pandas/io/parsers.py", line 454, in _read
    parser = TextFileReader(fp_or_buf, **kwds)
  File "/home/airflow/.local/lib/python3.6/site-packages/pandas/io/parsers.py", line 948, in __init__
    self._make_engine(self.engine)
  File "/home/airflow/.local/lib/python3.6/site-packages/pandas/io/parsers.py", line 1180, in _make_engine
    self._engine = CParserWrapper(self.f, **self.options)
  File "/home/airflow/.local/lib/python3.6/site-packages/pandas/io/parsers.py", line 2010, in __init__
    self._reader = parsers.TextReader(src, **kwds)
  File "pandas/_libs/parsers.pyx", line 382, in pandas._libs.parsers.TextReader.__cinit__
  File "pandas/_libs/parsers.pyx", line 674, in pandas._libs.parsers.TextReader._setup_parser_source
FileNotFoundError: [Errno 2] No such file or directory: 'C:\\Users\\amey sonje\\Downloads\\csv_data.csv'
[2021-08-12 06:14:04,010] {taskinstance.py:1551} INFO - Marking task as UP_FOR_RETRY. dag_id=pipeline_try, task_id=transform_data, execution_date=20210811T000000, start_date=20210812T061403, end_date=20210812T061404
[2021-08-12 06:14:04,078] {local_task_job.py:149} INFO - Task exited with return code 1
[2021-08-12 08:25:40,735] {taskinstance.py:896} INFO - Dependencies all met for <TaskInstance: pipeline_try.transform_data 2021-08-11T00:00:00+00:00 [queued]>
[2021-08-12 08:25:40,754] {taskinstance.py:896} INFO - Dependencies all met for <TaskInstance: pipeline_try.transform_data 2021-08-11T00:00:00+00:00 [queued]>
[2021-08-12 08:25:40,755] {taskinstance.py:1087} INFO - 
--------------------------------------------------------------------------------
[2021-08-12 08:25:40,755] {taskinstance.py:1088} INFO - Starting attempt 1 of 2
[2021-08-12 08:25:40,755] {taskinstance.py:1089} INFO - 
--------------------------------------------------------------------------------
[2021-08-12 08:25:40,769] {taskinstance.py:1107} INFO - Executing <Task(PythonOperator): transform_data> on 2021-08-11T00:00:00+00:00
[2021-08-12 08:25:40,773] {standard_task_runner.py:52} INFO - Started process 3066 to run task
[2021-08-12 08:25:40,778] {standard_task_runner.py:76} INFO - Running: ['***', 'tasks', 'run', 'pipeline_try', 'transform_data', '2021-08-11T00:00:00+00:00', '--job-id', '29', '--pool', 'default_pool', '--raw', '--subdir', 'DAGS_FOLDER/pipeline_try1.py', '--cfg-path', '/tmp/tmpkdoy_4wb', '--error-file', '/tmp/tmpy3q9e8zb']
[2021-08-12 08:25:40,782] {standard_task_runner.py:77} INFO - Job 29: Subtask transform_data
[2021-08-12 08:25:40,842] {logging_mixin.py:104} INFO - Running <TaskInstance: pipeline_try.transform_data 2021-08-11T00:00:00+00:00 [running]> on host 99300daf4d26
[2021-08-12 08:25:40,907] {taskinstance.py:1302} INFO - Exporting the following env vars:
AIRFLOW_CTX_DAG_EMAIL=ameysonje242000@gmail.com
AIRFLOW_CTX_DAG_OWNER=amey
AIRFLOW_CTX_DAG_ID=pipeline_try
AIRFLOW_CTX_TASK_ID=transform_data
AIRFLOW_CTX_EXECUTION_DATE=2021-08-11T00:00:00+00:00
AIRFLOW_CTX_DAG_RUN_ID=scheduled__2021-08-11T00:00:00+00:00
[2021-08-12 08:25:40,910] {logging_mixin.py:104} INFO - \opt\data\csv_data.csv
[2021-08-12 08:25:40,911] {logging_mixin.py:104} INFO - \opt\data\csv_data_transformed.csv
[2021-08-12 08:25:40,918] {taskinstance.py:1501} ERROR - Task failed with exception
Traceback (most recent call last):
  File "/home/airflow/.local/lib/python3.6/site-packages/airflow/models/taskinstance.py", line 1157, in _run_raw_task
    self._prepare_and_execute_task_with_callbacks(context, task)
  File "/home/airflow/.local/lib/python3.6/site-packages/airflow/models/taskinstance.py", line 1331, in _prepare_and_execute_task_with_callbacks
    result = self._execute_task(context, task_copy)
  File "/home/airflow/.local/lib/python3.6/site-packages/airflow/models/taskinstance.py", line 1361, in _execute_task
    result = task_copy.execute(context=context)
  File "/home/airflow/.local/lib/python3.6/site-packages/airflow/operators/python.py", line 150, in execute
    return_value = self.execute_callable()
  File "/home/airflow/.local/lib/python3.6/site-packages/airflow/operators/python.py", line 161, in execute_callable
    return self.python_callable(*self.op_args, **self.op_kwargs)
  File "/opt/airflow/dags/pipeline_try1.py", line 31, in transform_data
    usecols=['Year','Industry_name_NZSIOC']
  File "/home/airflow/.local/lib/python3.6/site-packages/pandas/io/parsers.py", line 688, in read_csv
    return _read(filepath_or_buffer, kwds)
  File "/home/airflow/.local/lib/python3.6/site-packages/pandas/io/parsers.py", line 454, in _read
    parser = TextFileReader(fp_or_buf, **kwds)
  File "/home/airflow/.local/lib/python3.6/site-packages/pandas/io/parsers.py", line 948, in __init__
    self._make_engine(self.engine)
  File "/home/airflow/.local/lib/python3.6/site-packages/pandas/io/parsers.py", line 1180, in _make_engine
    self._engine = CParserWrapper(self.f, **self.options)
  File "/home/airflow/.local/lib/python3.6/site-packages/pandas/io/parsers.py", line 2010, in __init__
    self._reader = parsers.TextReader(src, **kwds)
  File "pandas/_libs/parsers.pyx", line 382, in pandas._libs.parsers.TextReader.__cinit__
  File "pandas/_libs/parsers.pyx", line 674, in pandas._libs.parsers.TextReader._setup_parser_source
FileNotFoundError: [Errno 2] No such file or directory: '\\opt\\data\\csv_data.csv'
[2021-08-12 08:25:40,929] {taskinstance.py:1551} INFO - Marking task as UP_FOR_RETRY. dag_id=pipeline_try, task_id=transform_data, execution_date=20210811T000000, start_date=20210812T082540, end_date=20210812T082540
[2021-08-12 08:25:40,990] {local_task_job.py:149} INFO - Task exited with return code 1
[2021-08-12 08:29:42,102] {taskinstance.py:896} INFO - Dependencies all met for <TaskInstance: pipeline_try.transform_data 2021-08-11T00:00:00+00:00 [queued]>
[2021-08-12 08:29:42,125] {taskinstance.py:896} INFO - Dependencies all met for <TaskInstance: pipeline_try.transform_data 2021-08-11T00:00:00+00:00 [queued]>
[2021-08-12 08:29:42,126] {taskinstance.py:1087} INFO - 
--------------------------------------------------------------------------------
[2021-08-12 08:29:42,126] {taskinstance.py:1088} INFO - Starting attempt 1 of 2
[2021-08-12 08:29:42,127] {taskinstance.py:1089} INFO - 
--------------------------------------------------------------------------------
[2021-08-12 08:29:42,136] {taskinstance.py:1107} INFO - Executing <Task(PythonOperator): transform_data> on 2021-08-11T00:00:00+00:00
[2021-08-12 08:29:42,143] {standard_task_runner.py:52} INFO - Started process 4570 to run task
[2021-08-12 08:29:42,146] {standard_task_runner.py:76} INFO - Running: ['***', 'tasks', 'run', 'pipeline_try', 'transform_data', '2021-08-11T00:00:00+00:00', '--job-id', '30', '--pool', 'default_pool', '--raw', '--subdir', 'DAGS_FOLDER/pipeline_try1.py', '--cfg-path', '/tmp/tmpzmz1ha9n', '--error-file', '/tmp/tmpee5oyuut']
[2021-08-12 08:29:42,150] {standard_task_runner.py:77} INFO - Job 30: Subtask transform_data
[2021-08-12 08:29:42,203] {logging_mixin.py:104} INFO - Running <TaskInstance: pipeline_try.transform_data 2021-08-11T00:00:00+00:00 [running]> on host 99300daf4d26
[2021-08-12 08:29:42,263] {taskinstance.py:1302} INFO - Exporting the following env vars:
AIRFLOW_CTX_DAG_EMAIL=ameysonje242000@gmail.com
AIRFLOW_CTX_DAG_OWNER=amey
AIRFLOW_CTX_DAG_ID=pipeline_try
AIRFLOW_CTX_TASK_ID=transform_data
AIRFLOW_CTX_EXECUTION_DATE=2021-08-11T00:00:00+00:00
AIRFLOW_CTX_DAG_RUN_ID=scheduled__2021-08-11T00:00:00+00:00
[2021-08-12 08:29:42,265] {logging_mixin.py:104} INFO - /opt/data/csv_data.csv
[2021-08-12 08:29:42,265] {logging_mixin.py:104} INFO - /opt/data/csv_data_transformed.csv
[2021-08-12 08:29:42,649] {python.py:151} INFO - Done. Returned value was: None
[2021-08-12 08:29:42,666] {taskinstance.py:1211} INFO - Marking task as SUCCESS. dag_id=pipeline_try, task_id=transform_data, execution_date=20210811T000000, start_date=20210812T082942, end_date=20210812T082942
[2021-08-12 08:29:42,707] {taskinstance.py:1265} INFO - 0 downstream tasks scheduled from follow-on schedule check
[2021-08-12 08:29:42,721] {local_task_job.py:149} INFO - Task exited with return code 0
[2021-08-12 11:53:03,014] {taskinstance.py:896} INFO - Dependencies all met for <TaskInstance: pipeline_try.transform_data 2021-08-11T00:00:00+00:00 [queued]>
[2021-08-12 11:53:03,099] {taskinstance.py:896} INFO - Dependencies all met for <TaskInstance: pipeline_try.transform_data 2021-08-11T00:00:00+00:00 [queued]>
[2021-08-12 11:53:03,100] {taskinstance.py:1087} INFO - 
--------------------------------------------------------------------------------
[2021-08-12 11:53:03,102] {taskinstance.py:1088} INFO - Starting attempt 1 of 2
[2021-08-12 11:53:03,103] {taskinstance.py:1089} INFO - 
--------------------------------------------------------------------------------
[2021-08-12 11:53:03,150] {taskinstance.py:1107} INFO - Executing <Task(PythonOperator): transform_data> on 2021-08-11T00:00:00+00:00
[2021-08-12 11:53:03,179] {standard_task_runner.py:52} INFO - Started process 1766 to run task
[2021-08-12 11:53:03,201] {standard_task_runner.py:76} INFO - Running: ['***', 'tasks', 'run', 'pipeline_try', 'transform_data', '2021-08-11T00:00:00+00:00', '--job-id', '59', '--pool', 'default_pool', '--raw', '--subdir', 'DAGS_FOLDER/pipeline_try1.py', '--cfg-path', '/tmp/tmpgu6p1p9o', '--error-file', '/tmp/tmp9t9d25hn']
[2021-08-12 11:53:03,362] {standard_task_runner.py:77} INFO - Job 59: Subtask transform_data
[2021-08-12 11:53:04,455] {logging_mixin.py:104} INFO - Running <TaskInstance: pipeline_try.transform_data 2021-08-11T00:00:00+00:00 [running]> on host 99300daf4d26
[2021-08-12 11:53:04,783] {taskinstance.py:1302} INFO - Exporting the following env vars:
AIRFLOW_CTX_DAG_EMAIL=ameysonje242000@gmail.com
AIRFLOW_CTX_DAG_OWNER=amey
AIRFLOW_CTX_DAG_ID=pipeline_try
AIRFLOW_CTX_TASK_ID=transform_data
AIRFLOW_CTX_EXECUTION_DATE=2021-08-11T00:00:00+00:00
AIRFLOW_CTX_DAG_RUN_ID=scheduled__2021-08-11T00:00:00+00:00
[2021-08-12 11:53:04,801] {logging_mixin.py:104} INFO - /opt/data/csv_data.csv
[2021-08-12 11:53:04,826] {logging_mixin.py:104} INFO - /opt/data/csv_data_transformed.csv
[2021-08-12 11:53:05,587] {python.py:151} INFO - Done. Returned value was: None
[2021-08-12 11:53:05,616] {taskinstance.py:1211} INFO - Marking task as SUCCESS. dag_id=pipeline_try, task_id=transform_data, execution_date=20210811T000000, start_date=20210812T115303, end_date=20210812T115305
[2021-08-12 11:53:05,704] {taskinstance.py:1265} INFO - 1 downstream tasks scheduled from follow-on schedule check
[2021-08-12 11:53:05,755] {local_task_job.py:149} INFO - Task exited with return code 0
[2021-08-12 12:36:09,146] {taskinstance.py:896} INFO - Dependencies all met for <TaskInstance: pipeline_try.transform_data 2021-08-11T00:00:00+00:00 [queued]>
[2021-08-12 12:36:09,164] {taskinstance.py:896} INFO - Dependencies all met for <TaskInstance: pipeline_try.transform_data 2021-08-11T00:00:00+00:00 [queued]>
[2021-08-12 12:36:09,165] {taskinstance.py:1087} INFO - 
--------------------------------------------------------------------------------
[2021-08-12 12:36:09,166] {taskinstance.py:1088} INFO - Starting attempt 1 of 2
[2021-08-12 12:36:09,169] {taskinstance.py:1089} INFO - 
--------------------------------------------------------------------------------
[2021-08-12 12:36:09,187] {taskinstance.py:1107} INFO - Executing <Task(PythonOperator): transform_data> on 2021-08-11T00:00:00+00:00
[2021-08-12 12:36:09,197] {standard_task_runner.py:52} INFO - Started process 17296 to run task
[2021-08-12 12:36:09,202] {standard_task_runner.py:76} INFO - Running: ['***', 'tasks', 'run', 'pipeline_try', 'transform_data', '2021-08-11T00:00:00+00:00', '--job-id', '82', '--pool', 'default_pool', '--raw', '--subdir', 'DAGS_FOLDER/pipeline_try1.py', '--cfg-path', '/tmp/tmpm936x6lm', '--error-file', '/tmp/tmpzb0pl3z6']
[2021-08-12 12:36:09,206] {standard_task_runner.py:77} INFO - Job 82: Subtask transform_data
[2021-08-12 12:36:09,260] {logging_mixin.py:104} INFO - Running <TaskInstance: pipeline_try.transform_data 2021-08-11T00:00:00+00:00 [running]> on host 99300daf4d26
[2021-08-12 12:36:09,335] {taskinstance.py:1302} INFO - Exporting the following env vars:
AIRFLOW_CTX_DAG_EMAIL=ameysonje242000@gmail.com
AIRFLOW_CTX_DAG_OWNER=amey
AIRFLOW_CTX_DAG_ID=pipeline_try
AIRFLOW_CTX_TASK_ID=transform_data
AIRFLOW_CTX_EXECUTION_DATE=2021-08-11T00:00:00+00:00
AIRFLOW_CTX_DAG_RUN_ID=scheduled__2021-08-11T00:00:00+00:00
[2021-08-12 12:36:09,338] {logging_mixin.py:104} INFO - /opt/data/csv_data.csv
[2021-08-12 12:36:09,339] {logging_mixin.py:104} INFO - /opt/data/csv_data_transformed.csv
[2021-08-12 12:36:09,657] {python.py:151} INFO - Done. Returned value was: None
[2021-08-12 12:36:09,673] {taskinstance.py:1211} INFO - Marking task as SUCCESS. dag_id=pipeline_try, task_id=transform_data, execution_date=20210811T000000, start_date=20210812T123609, end_date=20210812T123609
[2021-08-12 12:36:09,716] {taskinstance.py:1265} INFO - 1 downstream tasks scheduled from follow-on schedule check
[2021-08-12 12:36:09,736] {local_task_job.py:149} INFO - Task exited with return code 0
