[2021-08-12 04:55:37,697] {taskinstance.py:896} INFO - Dependencies all met for <TaskInstance: pipeline_try.transform_data 2021-08-11T00:00:00+00:00 [queued]>
[2021-08-12 04:55:37,717] {taskinstance.py:896} INFO - Dependencies all met for <TaskInstance: pipeline_try.transform_data 2021-08-11T00:00:00+00:00 [queued]>
[2021-08-12 04:55:37,718] {taskinstance.py:1087} INFO - 
--------------------------------------------------------------------------------
[2021-08-12 04:55:37,718] {taskinstance.py:1088} INFO - Starting attempt 2 of 2
[2021-08-12 04:55:37,719] {taskinstance.py:1089} INFO - 
--------------------------------------------------------------------------------
[2021-08-12 04:55:37,730] {taskinstance.py:1107} INFO - Executing <Task(PythonOperator): transform_data> on 2021-08-11T00:00:00+00:00
[2021-08-12 04:55:37,735] {standard_task_runner.py:52} INFO - Started process 2107 to run task
[2021-08-12 04:55:37,740] {standard_task_runner.py:76} INFO - Running: ['***', 'tasks', 'run', 'pipeline_try', 'transform_data', '2021-08-11T00:00:00+00:00', '--job-id', '17', '--pool', 'default_pool', '--raw', '--subdir', 'DAGS_FOLDER/pipeline_try1.py', '--cfg-path', '/tmp/tmpp3i5khd3', '--error-file', '/tmp/tmpougzssfn']
[2021-08-12 04:55:37,744] {standard_task_runner.py:77} INFO - Job 17: Subtask transform_data
[2021-08-12 04:55:37,800] {logging_mixin.py:104} INFO - Running <TaskInstance: pipeline_try.transform_data 2021-08-11T00:00:00+00:00 [running]> on host 9d72a0011461
[2021-08-12 04:55:37,863] {taskinstance.py:1302} INFO - Exporting the following env vars:
AIRFLOW_CTX_DAG_EMAIL=ameysonje242000@gmail.com
AIRFLOW_CTX_DAG_OWNER=amey
AIRFLOW_CTX_DAG_ID=pipeline_try
AIRFLOW_CTX_TASK_ID=transform_data
AIRFLOW_CTX_EXECUTION_DATE=2021-08-11T00:00:00+00:00
AIRFLOW_CTX_DAG_RUN_ID=scheduled__2021-08-11T00:00:00+00:00
[2021-08-12 04:55:37,866] {logging_mixin.py:104} INFO - C:\Users\amey sonje\Downloads\csv_data.csv
[2021-08-12 04:55:37,866] {logging_mixin.py:104} INFO - C:\Users\amey sonje\Downloads\csv_data_transformed.csv
[2021-08-12 04:55:37,870] {taskinstance.py:1501} ERROR - Task failed with exception
Traceback (most recent call last):
  File "/home/airflow/.local/lib/python3.6/site-packages/airflow/models/taskinstance.py", line 1157, in _run_raw_task
    self._prepare_and_execute_task_with_callbacks(context, task)
  File "/home/airflow/.local/lib/python3.6/site-packages/airflow/models/taskinstance.py", line 1331, in _prepare_and_execute_task_with_callbacks
    result = self._execute_task(context, task_copy)
  File "/home/airflow/.local/lib/python3.6/site-packages/airflow/models/taskinstance.py", line 1361, in _execute_task
    result = task_copy.execute(context=context)
  File "/home/airflow/.local/lib/python3.6/site-packages/airflow/operators/python.py", line 150, in execute
    return_value = self.execute_callable()
  File "/home/airflow/.local/lib/python3.6/site-packages/airflow/operators/python.py", line 161, in execute_callable
    return self.python_callable(*self.op_args, **self.op_kwargs)
  File "/opt/airflow/dags/pipeline_try1.py", line 31, in transform_data
    usecols=['Year','Industry_name_NZSIOC']
  File "/home/airflow/.local/lib/python3.6/site-packages/pandas/io/parsers.py", line 688, in read_csv
    return _read(filepath_or_buffer, kwds)
  File "/home/airflow/.local/lib/python3.6/site-packages/pandas/io/parsers.py", line 454, in _read
    parser = TextFileReader(fp_or_buf, **kwds)
  File "/home/airflow/.local/lib/python3.6/site-packages/pandas/io/parsers.py", line 948, in __init__
    self._make_engine(self.engine)
  File "/home/airflow/.local/lib/python3.6/site-packages/pandas/io/parsers.py", line 1180, in _make_engine
    self._engine = CParserWrapper(self.f, **self.options)
  File "/home/airflow/.local/lib/python3.6/site-packages/pandas/io/parsers.py", line 2010, in __init__
    self._reader = parsers.TextReader(src, **kwds)
  File "pandas/_libs/parsers.pyx", line 382, in pandas._libs.parsers.TextReader.__cinit__
  File "pandas/_libs/parsers.pyx", line 674, in pandas._libs.parsers.TextReader._setup_parser_source
FileNotFoundError: [Errno 2] No such file or directory: 'C:\\Users\\amey sonje\\Downloads\\csv_data.csv'
[2021-08-12 04:55:37,882] {taskinstance.py:1551} INFO - Marking task as FAILED. dag_id=pipeline_try, task_id=transform_data, execution_date=20210811T000000, start_date=20210812T045537, end_date=20210812T045537
[2021-08-12 04:55:37,912] {local_task_job.py:149} INFO - Task exited with return code 1
[2021-08-12 06:19:05,274] {taskinstance.py:896} INFO - Dependencies all met for <TaskInstance: pipeline_try.transform_data 2021-08-11T00:00:00+00:00 [queued]>
[2021-08-12 06:19:05,363] {taskinstance.py:896} INFO - Dependencies all met for <TaskInstance: pipeline_try.transform_data 2021-08-11T00:00:00+00:00 [queued]>
[2021-08-12 06:19:05,364] {taskinstance.py:1087} INFO - 
--------------------------------------------------------------------------------
[2021-08-12 06:19:05,364] {taskinstance.py:1088} INFO - Starting attempt 2 of 2
[2021-08-12 06:19:05,364] {taskinstance.py:1089} INFO - 
--------------------------------------------------------------------------------
[2021-08-12 06:19:05,373] {taskinstance.py:1107} INFO - Executing <Task(PythonOperator): transform_data> on 2021-08-11T00:00:00+00:00
[2021-08-12 06:19:05,377] {standard_task_runner.py:52} INFO - Started process 2693 to run task
[2021-08-12 06:19:05,382] {standard_task_runner.py:76} INFO - Running: ['***', 'tasks', 'run', 'pipeline_try', 'transform_data', '2021-08-11T00:00:00+00:00', '--job-id', '24', '--pool', 'default_pool', '--raw', '--subdir', 'DAGS_FOLDER/pipeline_try1.py', '--cfg-path', '/tmp/tmphtr5yqab', '--error-file', '/tmp/tmpxl9_445p']
[2021-08-12 06:19:05,387] {standard_task_runner.py:77} INFO - Job 24: Subtask transform_data
[2021-08-12 06:19:05,439] {logging_mixin.py:104} INFO - Running <TaskInstance: pipeline_try.transform_data 2021-08-11T00:00:00+00:00 [running]> on host a84373444557
[2021-08-12 06:19:05,489] {taskinstance.py:1302} INFO - Exporting the following env vars:
AIRFLOW_CTX_DAG_EMAIL=ameysonje242000@gmail.com
AIRFLOW_CTX_DAG_OWNER=amey
AIRFLOW_CTX_DAG_ID=pipeline_try
AIRFLOW_CTX_TASK_ID=transform_data
AIRFLOW_CTX_EXECUTION_DATE=2021-08-11T00:00:00+00:00
AIRFLOW_CTX_DAG_RUN_ID=scheduled__2021-08-11T00:00:00+00:00
[2021-08-12 06:19:05,491] {logging_mixin.py:104} INFO - C:\Users\amey sonje\Downloads\csv_data.csv
[2021-08-12 06:19:05,491] {logging_mixin.py:104} INFO - C:\Users\amey sonje\Downloads\csv_data_transformed.csv
[2021-08-12 06:19:05,493] {taskinstance.py:1501} ERROR - Task failed with exception
Traceback (most recent call last):
  File "/home/airflow/.local/lib/python3.6/site-packages/airflow/models/taskinstance.py", line 1157, in _run_raw_task
    self._prepare_and_execute_task_with_callbacks(context, task)
  File "/home/airflow/.local/lib/python3.6/site-packages/airflow/models/taskinstance.py", line 1331, in _prepare_and_execute_task_with_callbacks
    result = self._execute_task(context, task_copy)
  File "/home/airflow/.local/lib/python3.6/site-packages/airflow/models/taskinstance.py", line 1361, in _execute_task
    result = task_copy.execute(context=context)
  File "/home/airflow/.local/lib/python3.6/site-packages/airflow/operators/python.py", line 150, in execute
    return_value = self.execute_callable()
  File "/home/airflow/.local/lib/python3.6/site-packages/airflow/operators/python.py", line 161, in execute_callable
    return self.python_callable(*self.op_args, **self.op_kwargs)
  File "/opt/airflow/dags/pipeline_try1.py", line 31, in transform_data
    usecols=['Year','Industry_name_NZSIOC']
  File "/home/airflow/.local/lib/python3.6/site-packages/pandas/io/parsers.py", line 688, in read_csv
    return _read(filepath_or_buffer, kwds)
  File "/home/airflow/.local/lib/python3.6/site-packages/pandas/io/parsers.py", line 454, in _read
    parser = TextFileReader(fp_or_buf, **kwds)
  File "/home/airflow/.local/lib/python3.6/site-packages/pandas/io/parsers.py", line 948, in __init__
    self._make_engine(self.engine)
  File "/home/airflow/.local/lib/python3.6/site-packages/pandas/io/parsers.py", line 1180, in _make_engine
    self._engine = CParserWrapper(self.f, **self.options)
  File "/home/airflow/.local/lib/python3.6/site-packages/pandas/io/parsers.py", line 2010, in __init__
    self._reader = parsers.TextReader(src, **kwds)
  File "pandas/_libs/parsers.pyx", line 382, in pandas._libs.parsers.TextReader.__cinit__
  File "pandas/_libs/parsers.pyx", line 674, in pandas._libs.parsers.TextReader._setup_parser_source
FileNotFoundError: [Errno 2] No such file or directory: 'C:\\Users\\amey sonje\\Downloads\\csv_data.csv'
[2021-08-12 06:19:05,499] {taskinstance.py:1551} INFO - Marking task as FAILED. dag_id=pipeline_try, task_id=transform_data, execution_date=20210811T000000, start_date=20210812T061905, end_date=20210812T061905
[2021-08-12 06:19:05,553] {local_task_job.py:149} INFO - Task exited with return code 1
