[2021-08-13 09:21:35,766] {taskinstance.py:896} INFO - Dependencies all met for <TaskInstance: pipeline_try.transform_data 2021-08-13T09:21:33.871792+00:00 [queued]>
[2021-08-13 09:21:35,781] {taskinstance.py:896} INFO - Dependencies all met for <TaskInstance: pipeline_try.transform_data 2021-08-13T09:21:33.871792+00:00 [queued]>
[2021-08-13 09:21:35,782] {taskinstance.py:1087} INFO - 
--------------------------------------------------------------------------------
[2021-08-13 09:21:35,782] {taskinstance.py:1088} INFO - Starting attempt 1 of 2
[2021-08-13 09:21:35,782] {taskinstance.py:1089} INFO - 
--------------------------------------------------------------------------------
[2021-08-13 09:21:35,791] {taskinstance.py:1107} INFO - Executing <Task(PythonOperator): transform_data> on 2021-08-13T09:21:33.871792+00:00
[2021-08-13 09:21:35,795] {standard_task_runner.py:52} INFO - Started process 20456 to run task
[2021-08-13 09:21:35,800] {standard_task_runner.py:76} INFO - Running: ['***', 'tasks', 'run', 'pipeline_try', 'transform_data', '2021-08-13T09:21:33.871792+00:00', '--job-id', '167', '--pool', 'default_pool', '--raw', '--subdir', 'DAGS_FOLDER/pipeline_try1.py', '--cfg-path', '/tmp/tmpy55is4pf', '--error-file', '/tmp/tmpug04pav5']
[2021-08-13 09:21:35,804] {standard_task_runner.py:77} INFO - Job 167: Subtask transform_data
[2021-08-13 09:21:35,852] {logging_mixin.py:104} INFO - Running <TaskInstance: pipeline_try.transform_data 2021-08-13T09:21:33.871792+00:00 [running]> on host 99300daf4d26
[2021-08-13 09:21:35,899] {taskinstance.py:1302} INFO - Exporting the following env vars:
AIRFLOW_CTX_DAG_EMAIL=ameysonje242000@gmail.com
AIRFLOW_CTX_DAG_OWNER=amey
AIRFLOW_CTX_DAG_ID=pipeline_try
AIRFLOW_CTX_TASK_ID=transform_data
AIRFLOW_CTX_EXECUTION_DATE=2021-08-13T09:21:33.871792+00:00
AIRFLOW_CTX_DAG_RUN_ID=manual__2021-08-13T09:21:33.871792+00:00
[2021-08-13 09:21:35,901] {logging_mixin.py:104} INFO - /opt/data/csv_data.csv
[2021-08-13 09:21:35,902] {logging_mixin.py:104} INFO - /opt/data/csv_data_transformed.csv
[2021-08-13 09:21:36,022] {taskinstance.py:1501} ERROR - Task failed with exception
Traceback (most recent call last):
  File "/home/airflow/.local/lib/python3.6/site-packages/airflow/models/taskinstance.py", line 1157, in _run_raw_task
    self._prepare_and_execute_task_with_callbacks(context, task)
  File "/home/airflow/.local/lib/python3.6/site-packages/airflow/models/taskinstance.py", line 1331, in _prepare_and_execute_task_with_callbacks
    result = self._execute_task(context, task_copy)
  File "/home/airflow/.local/lib/python3.6/site-packages/airflow/models/taskinstance.py", line 1361, in _execute_task
    result = task_copy.execute(context=context)
  File "/home/airflow/.local/lib/python3.6/site-packages/airflow/operators/python.py", line 150, in execute
    return_value = self.execute_callable()
  File "/home/airflow/.local/lib/python3.6/site-packages/airflow/operators/python.py", line 161, in execute_callable
    return self.python_callable(*self.op_args, **self.op_kwargs)
  File "/opt/airflow/dags/pipeline_try1.py", line 37, in transform_data
    csv_data.to_csv(path_or_buf=transformed_csv_path)
  File "/home/airflow/.local/lib/python3.6/site-packages/pandas/core/generic.py", line 3170, in to_csv
    formatter.save()
  File "/home/airflow/.local/lib/python3.6/site-packages/pandas/io/formats/csvs.py", line 190, in save
    compression=dict(self.compression_args, method=self.compression),
  File "/home/airflow/.local/lib/python3.6/site-packages/pandas/io/common.py", line 493, in get_handle
    f = open(path_or_buf, mode, encoding=encoding, errors=errors, newline="")
PermissionError: [Errno 13] Permission denied: '/opt/data/csv_data_transformed.csv'
[2021-08-13 09:21:36,034] {taskinstance.py:1551} INFO - Marking task as UP_FOR_RETRY. dag_id=pipeline_try, task_id=transform_data, execution_date=20210813T092133, start_date=20210813T092135, end_date=20210813T092136
[2021-08-13 09:21:36,092] {local_task_job.py:149} INFO - Task exited with return code 1
