[2021-08-11 15:58:32,760] {taskinstance.py:896} INFO - Dependencies all met for <TaskInstance: pipeline_try.transform_data 2021-08-10T00:00:00+00:00 [queued]>
[2021-08-11 15:58:32,780] {taskinstance.py:896} INFO - Dependencies all met for <TaskInstance: pipeline_try.transform_data 2021-08-10T00:00:00+00:00 [queued]>
[2021-08-11 15:58:32,781] {taskinstance.py:1087} INFO - 
--------------------------------------------------------------------------------
[2021-08-11 15:58:32,781] {taskinstance.py:1088} INFO - Starting attempt 1 of 2
[2021-08-11 15:58:32,781] {taskinstance.py:1089} INFO - 
--------------------------------------------------------------------------------
[2021-08-11 15:58:32,794] {taskinstance.py:1107} INFO - Executing <Task(PythonOperator): transform_data> on 2021-08-10T00:00:00+00:00
[2021-08-11 15:58:32,798] {standard_task_runner.py:52} INFO - Started process 1317 to run task
[2021-08-11 15:58:32,802] {standard_task_runner.py:76} INFO - Running: ['***', 'tasks', 'run', 'pipeline_try', 'transform_data', '2021-08-10T00:00:00+00:00', '--job-id', '2', '--pool', 'default_pool', '--raw', '--subdir', 'DAGS_FOLDER/pipeline_try1.py', '--cfg-path', '/tmp/tmp7qijldrx', '--error-file', '/tmp/tmpa5a_sedy']
[2021-08-11 15:58:32,809] {standard_task_runner.py:77} INFO - Job 2: Subtask transform_data
[2021-08-11 15:58:32,862] {logging_mixin.py:104} INFO - Running <TaskInstance: pipeline_try.transform_data 2021-08-10T00:00:00+00:00 [running]> on host 9d72a0011461
[2021-08-11 15:58:32,929] {taskinstance.py:1302} INFO - Exporting the following env vars:
AIRFLOW_CTX_DAG_EMAIL=ameysonje242000@gmail.com
AIRFLOW_CTX_DAG_OWNER=amey
AIRFLOW_CTX_DAG_ID=pipeline_try
AIRFLOW_CTX_TASK_ID=transform_data
AIRFLOW_CTX_EXECUTION_DATE=2021-08-10T00:00:00+00:00
AIRFLOW_CTX_DAG_RUN_ID=scheduled__2021-08-10T00:00:00+00:00
[2021-08-11 15:58:32,931] {logging_mixin.py:104} INFO - C:\Users\amey sonje\Downloads/annual-enterprise-survey-2020-financial-year-provisional-csv.csv
[2021-08-11 15:58:32,932] {logging_mixin.py:104} INFO - C:\Users\amey sonje\Downloads/annual-enterprise-survey-2020-financial-year-provisional-csv-transformed.csv
[2021-08-11 15:58:32,938] {taskinstance.py:1501} ERROR - Task failed with exception
Traceback (most recent call last):
  File "/home/airflow/.local/lib/python3.6/site-packages/airflow/models/taskinstance.py", line 1157, in _run_raw_task
    self._prepare_and_execute_task_with_callbacks(context, task)
  File "/home/airflow/.local/lib/python3.6/site-packages/airflow/models/taskinstance.py", line 1331, in _prepare_and_execute_task_with_callbacks
    result = self._execute_task(context, task_copy)
  File "/home/airflow/.local/lib/python3.6/site-packages/airflow/models/taskinstance.py", line 1361, in _execute_task
    result = task_copy.execute(context=context)
  File "/home/airflow/.local/lib/python3.6/site-packages/airflow/operators/python.py", line 150, in execute
    return_value = self.execute_callable()
  File "/home/airflow/.local/lib/python3.6/site-packages/airflow/operators/python.py", line 161, in execute_callable
    return self.python_callable(*self.op_args, **self.op_kwargs)
  File "/opt/airflow/dags/pipeline_try1.py", line 31, in transform_data
    usecols=['Year','Industry_name_NZSIOC']
  File "/home/airflow/.local/lib/python3.6/site-packages/pandas/io/parsers.py", line 688, in read_csv
    return _read(filepath_or_buffer, kwds)
  File "/home/airflow/.local/lib/python3.6/site-packages/pandas/io/parsers.py", line 454, in _read
    parser = TextFileReader(fp_or_buf, **kwds)
  File "/home/airflow/.local/lib/python3.6/site-packages/pandas/io/parsers.py", line 948, in __init__
    self._make_engine(self.engine)
  File "/home/airflow/.local/lib/python3.6/site-packages/pandas/io/parsers.py", line 1180, in _make_engine
    self._engine = CParserWrapper(self.f, **self.options)
  File "/home/airflow/.local/lib/python3.6/site-packages/pandas/io/parsers.py", line 2010, in __init__
    self._reader = parsers.TextReader(src, **kwds)
  File "pandas/_libs/parsers.pyx", line 382, in pandas._libs.parsers.TextReader.__cinit__
  File "pandas/_libs/parsers.pyx", line 674, in pandas._libs.parsers.TextReader._setup_parser_source
FileNotFoundError: [Errno 2] No such file or directory: 'C:\\Users\\amey sonje\\Downloads/annual-enterprise-survey-2020-financial-year-provisional-csv.csv'
[2021-08-11 15:58:32,948] {taskinstance.py:1551} INFO - Marking task as UP_FOR_RETRY. dag_id=pipeline_try, task_id=transform_data, execution_date=20210810T000000, start_date=20210811T155832, end_date=20210811T155832
[2021-08-11 15:58:32,976] {local_task_job.py:149} INFO - Task exited with return code 1
[2021-08-11 16:42:01,313] {taskinstance.py:896} INFO - Dependencies all met for <TaskInstance: pipeline_try.transform_data 2021-08-10T00:00:00+00:00 [queued]>
[2021-08-11 16:42:01,337] {taskinstance.py:896} INFO - Dependencies all met for <TaskInstance: pipeline_try.transform_data 2021-08-10T00:00:00+00:00 [queued]>
[2021-08-11 16:42:01,338] {taskinstance.py:1087} INFO - 
--------------------------------------------------------------------------------
[2021-08-11 16:42:01,339] {taskinstance.py:1088} INFO - Starting attempt 1 of 2
[2021-08-11 16:42:01,339] {taskinstance.py:1089} INFO - 
--------------------------------------------------------------------------------
[2021-08-11 16:42:01,352] {taskinstance.py:1107} INFO - Executing <Task(PythonOperator): transform_data> on 2021-08-10T00:00:00+00:00
[2021-08-11 16:42:01,358] {standard_task_runner.py:52} INFO - Started process 17975 to run task
[2021-08-11 16:42:01,363] {standard_task_runner.py:76} INFO - Running: ['***', 'tasks', 'run', 'pipeline_try', 'transform_data', '2021-08-10T00:00:00+00:00', '--job-id', '12', '--pool', 'default_pool', '--raw', '--subdir', 'DAGS_FOLDER/pipeline_try1.py', '--cfg-path', '/tmp/tmpig_ozzo4', '--error-file', '/tmp/tmpn202vrl5']
[2021-08-11 16:42:01,371] {standard_task_runner.py:77} INFO - Job 12: Subtask transform_data
[2021-08-11 16:42:01,437] {logging_mixin.py:104} INFO - Running <TaskInstance: pipeline_try.transform_data 2021-08-10T00:00:00+00:00 [running]> on host 9d72a0011461
[2021-08-11 16:42:01,505] {taskinstance.py:1302} INFO - Exporting the following env vars:
AIRFLOW_CTX_DAG_EMAIL=ameysonje242000@gmail.com
AIRFLOW_CTX_DAG_OWNER=amey
AIRFLOW_CTX_DAG_ID=pipeline_try
AIRFLOW_CTX_TASK_ID=transform_data
AIRFLOW_CTX_EXECUTION_DATE=2021-08-10T00:00:00+00:00
AIRFLOW_CTX_DAG_RUN_ID=scheduled__2021-08-10T00:00:00+00:00
[2021-08-11 16:42:01,507] {logging_mixin.py:104} INFO - C:\Users\amey sonje\Downloads\csv_data.csv
[2021-08-11 16:42:01,508] {logging_mixin.py:104} INFO - C:\Users\amey sonje\Downloads\csv_data_transformed.csv
[2021-08-11 16:42:01,511] {taskinstance.py:1501} ERROR - Task failed with exception
Traceback (most recent call last):
  File "/home/airflow/.local/lib/python3.6/site-packages/airflow/models/taskinstance.py", line 1157, in _run_raw_task
    self._prepare_and_execute_task_with_callbacks(context, task)
  File "/home/airflow/.local/lib/python3.6/site-packages/airflow/models/taskinstance.py", line 1331, in _prepare_and_execute_task_with_callbacks
    result = self._execute_task(context, task_copy)
  File "/home/airflow/.local/lib/python3.6/site-packages/airflow/models/taskinstance.py", line 1361, in _execute_task
    result = task_copy.execute(context=context)
  File "/home/airflow/.local/lib/python3.6/site-packages/airflow/operators/python.py", line 150, in execute
    return_value = self.execute_callable()
  File "/home/airflow/.local/lib/python3.6/site-packages/airflow/operators/python.py", line 161, in execute_callable
    return self.python_callable(*self.op_args, **self.op_kwargs)
  File "/opt/airflow/dags/pipeline_try1.py", line 31, in transform_data
    usecols=['Year','Industry_name_NZSIOC']
  File "/home/airflow/.local/lib/python3.6/site-packages/pandas/io/parsers.py", line 688, in read_csv
    return _read(filepath_or_buffer, kwds)
  File "/home/airflow/.local/lib/python3.6/site-packages/pandas/io/parsers.py", line 454, in _read
    parser = TextFileReader(fp_or_buf, **kwds)
  File "/home/airflow/.local/lib/python3.6/site-packages/pandas/io/parsers.py", line 948, in __init__
    self._make_engine(self.engine)
  File "/home/airflow/.local/lib/python3.6/site-packages/pandas/io/parsers.py", line 1180, in _make_engine
    self._engine = CParserWrapper(self.f, **self.options)
  File "/home/airflow/.local/lib/python3.6/site-packages/pandas/io/parsers.py", line 2010, in __init__
    self._reader = parsers.TextReader(src, **kwds)
  File "pandas/_libs/parsers.pyx", line 382, in pandas._libs.parsers.TextReader.__cinit__
  File "pandas/_libs/parsers.pyx", line 674, in pandas._libs.parsers.TextReader._setup_parser_source
FileNotFoundError: [Errno 2] No such file or directory: 'C:\\Users\\amey sonje\\Downloads\\csv_data.csv'
[2021-08-11 16:42:01,520] {taskinstance.py:1551} INFO - Marking task as UP_FOR_RETRY. dag_id=pipeline_try, task_id=transform_data, execution_date=20210810T000000, start_date=20210811T164201, end_date=20210811T164201
[2021-08-11 16:42:01,575] {local_task_job.py:149} INFO - Task exited with return code 1
