[2021-08-11 16:03:34,707] {taskinstance.py:896} INFO - Dependencies all met for <TaskInstance: pipeline_try.transform_data 2021-08-10T00:00:00+00:00 [queued]>
[2021-08-11 16:03:34,733] {taskinstance.py:896} INFO - Dependencies all met for <TaskInstance: pipeline_try.transform_data 2021-08-10T00:00:00+00:00 [queued]>
[2021-08-11 16:03:34,734] {taskinstance.py:1087} INFO - 
--------------------------------------------------------------------------------
[2021-08-11 16:03:34,734] {taskinstance.py:1088} INFO - Starting attempt 2 of 2
[2021-08-11 16:03:34,735] {taskinstance.py:1089} INFO - 
--------------------------------------------------------------------------------
[2021-08-11 16:03:34,746] {taskinstance.py:1107} INFO - Executing <Task(PythonOperator): transform_data> on 2021-08-10T00:00:00+00:00
[2021-08-11 16:03:34,752] {standard_task_runner.py:52} INFO - Started process 3273 to run task
[2021-08-11 16:03:34,761] {standard_task_runner.py:76} INFO - Running: ['***', 'tasks', 'run', 'pipeline_try', 'transform_data', '2021-08-10T00:00:00+00:00', '--job-id', '5', '--pool', 'default_pool', '--raw', '--subdir', 'DAGS_FOLDER/pipeline_try1.py', '--cfg-path', '/tmp/tmpklmkodj2', '--error-file', '/tmp/tmp0zowbqhg']
[2021-08-11 16:03:34,771] {standard_task_runner.py:77} INFO - Job 5: Subtask transform_data
[2021-08-11 16:03:34,849] {logging_mixin.py:104} INFO - Running <TaskInstance: pipeline_try.transform_data 2021-08-10T00:00:00+00:00 [running]> on host 9d72a0011461
[2021-08-11 16:03:34,926] {taskinstance.py:1302} INFO - Exporting the following env vars:
AIRFLOW_CTX_DAG_EMAIL=ameysonje242000@gmail.com
AIRFLOW_CTX_DAG_OWNER=amey
AIRFLOW_CTX_DAG_ID=pipeline_try
AIRFLOW_CTX_TASK_ID=transform_data
AIRFLOW_CTX_EXECUTION_DATE=2021-08-10T00:00:00+00:00
AIRFLOW_CTX_DAG_RUN_ID=scheduled__2021-08-10T00:00:00+00:00
[2021-08-11 16:03:34,929] {logging_mixin.py:104} INFO - C:\Users\amey sonje\Downloads\annual-enterprise-survey-2020-financial-year-provisional-csv.csv
[2021-08-11 16:03:34,930] {logging_mixin.py:104} INFO - C:\Users\amey sonje\Downloads\annual-enterprise-survey-2020-financial-year-provisional-csv-transformed.csv
[2021-08-11 16:03:34,932] {taskinstance.py:1501} ERROR - Task failed with exception
Traceback (most recent call last):
  File "/home/airflow/.local/lib/python3.6/site-packages/airflow/models/taskinstance.py", line 1157, in _run_raw_task
    self._prepare_and_execute_task_with_callbacks(context, task)
  File "/home/airflow/.local/lib/python3.6/site-packages/airflow/models/taskinstance.py", line 1331, in _prepare_and_execute_task_with_callbacks
    result = self._execute_task(context, task_copy)
  File "/home/airflow/.local/lib/python3.6/site-packages/airflow/models/taskinstance.py", line 1361, in _execute_task
    result = task_copy.execute(context=context)
  File "/home/airflow/.local/lib/python3.6/site-packages/airflow/operators/python.py", line 150, in execute
    return_value = self.execute_callable()
  File "/home/airflow/.local/lib/python3.6/site-packages/airflow/operators/python.py", line 161, in execute_callable
    return self.python_callable(*self.op_args, **self.op_kwargs)
  File "/opt/airflow/dags/pipeline_try1.py", line 31, in transform_data
    usecols=['Year','Industry_name_NZSIOC']
  File "/home/airflow/.local/lib/python3.6/site-packages/pandas/io/parsers.py", line 688, in read_csv
    return _read(filepath_or_buffer, kwds)
  File "/home/airflow/.local/lib/python3.6/site-packages/pandas/io/parsers.py", line 454, in _read
    parser = TextFileReader(fp_or_buf, **kwds)
  File "/home/airflow/.local/lib/python3.6/site-packages/pandas/io/parsers.py", line 948, in __init__
    self._make_engine(self.engine)
  File "/home/airflow/.local/lib/python3.6/site-packages/pandas/io/parsers.py", line 1180, in _make_engine
    self._engine = CParserWrapper(self.f, **self.options)
  File "/home/airflow/.local/lib/python3.6/site-packages/pandas/io/parsers.py", line 2010, in __init__
    self._reader = parsers.TextReader(src, **kwds)
  File "pandas/_libs/parsers.pyx", line 382, in pandas._libs.parsers.TextReader.__cinit__
  File "pandas/_libs/parsers.pyx", line 674, in pandas._libs.parsers.TextReader._setup_parser_source
FileNotFoundError: [Errno 2] No such file or directory: 'C:\\Users\\amey sonje\\Downloads\\annual-enterprise-survey-2020-financial-year-provisional-csv.csv'
[2021-08-11 16:03:34,944] {taskinstance.py:1551} INFO - Marking task as FAILED. dag_id=pipeline_try, task_id=transform_data, execution_date=20210810T000000, start_date=20210811T160334, end_date=20210811T160334
[2021-08-11 16:03:35,012] {local_task_job.py:149} INFO - Task exited with return code 1
[2021-08-11 16:47:03,708] {taskinstance.py:896} INFO - Dependencies all met for <TaskInstance: pipeline_try.transform_data 2021-08-10T00:00:00+00:00 [queued]>
[2021-08-11 16:47:03,762] {taskinstance.py:896} INFO - Dependencies all met for <TaskInstance: pipeline_try.transform_data 2021-08-10T00:00:00+00:00 [queued]>
[2021-08-11 16:47:03,764] {taskinstance.py:1087} INFO - 
--------------------------------------------------------------------------------
[2021-08-11 16:47:03,765] {taskinstance.py:1088} INFO - Starting attempt 2 of 2
[2021-08-11 16:47:03,766] {taskinstance.py:1089} INFO - 
--------------------------------------------------------------------------------
[2021-08-11 16:47:03,795] {taskinstance.py:1107} INFO - Executing <Task(PythonOperator): transform_data> on 2021-08-10T00:00:00+00:00
[2021-08-11 16:47:03,809] {standard_task_runner.py:52} INFO - Started process 19844 to run task
[2021-08-11 16:47:03,822] {standard_task_runner.py:76} INFO - Running: ['***', 'tasks', 'run', 'pipeline_try', 'transform_data', '2021-08-10T00:00:00+00:00', '--job-id', '13', '--pool', 'default_pool', '--raw', '--subdir', 'DAGS_FOLDER/pipeline_try1.py', '--cfg-path', '/tmp/tmpaxwg1g4v', '--error-file', '/tmp/tmpzlcnb5o6']
[2021-08-11 16:47:03,835] {standard_task_runner.py:77} INFO - Job 13: Subtask transform_data
[2021-08-11 16:47:03,992] {logging_mixin.py:104} INFO - Running <TaskInstance: pipeline_try.transform_data 2021-08-10T00:00:00+00:00 [running]> on host 9d72a0011461
[2021-08-11 16:47:04,191] {taskinstance.py:1302} INFO - Exporting the following env vars:
AIRFLOW_CTX_DAG_EMAIL=ameysonje242000@gmail.com
AIRFLOW_CTX_DAG_OWNER=amey
AIRFLOW_CTX_DAG_ID=pipeline_try
AIRFLOW_CTX_TASK_ID=transform_data
AIRFLOW_CTX_EXECUTION_DATE=2021-08-10T00:00:00+00:00
AIRFLOW_CTX_DAG_RUN_ID=scheduled__2021-08-10T00:00:00+00:00
[2021-08-11 16:47:04,198] {logging_mixin.py:104} INFO - C:\Users\amey sonje\Downloads\csv_data.csv
[2021-08-11 16:47:04,200] {logging_mixin.py:104} INFO - C:\Users\amey sonje\Downloads\csv_data_transformed.csv
[2021-08-11 16:47:04,204] {taskinstance.py:1501} ERROR - Task failed with exception
Traceback (most recent call last):
  File "/home/airflow/.local/lib/python3.6/site-packages/airflow/models/taskinstance.py", line 1157, in _run_raw_task
    self._prepare_and_execute_task_with_callbacks(context, task)
  File "/home/airflow/.local/lib/python3.6/site-packages/airflow/models/taskinstance.py", line 1331, in _prepare_and_execute_task_with_callbacks
    result = self._execute_task(context, task_copy)
  File "/home/airflow/.local/lib/python3.6/site-packages/airflow/models/taskinstance.py", line 1361, in _execute_task
    result = task_copy.execute(context=context)
  File "/home/airflow/.local/lib/python3.6/site-packages/airflow/operators/python.py", line 150, in execute
    return_value = self.execute_callable()
  File "/home/airflow/.local/lib/python3.6/site-packages/airflow/operators/python.py", line 161, in execute_callable
    return self.python_callable(*self.op_args, **self.op_kwargs)
  File "/opt/airflow/dags/pipeline_try1.py", line 31, in transform_data
    usecols=['Year','Industry_name_NZSIOC']
  File "/home/airflow/.local/lib/python3.6/site-packages/pandas/io/parsers.py", line 688, in read_csv
    return _read(filepath_or_buffer, kwds)
  File "/home/airflow/.local/lib/python3.6/site-packages/pandas/io/parsers.py", line 454, in _read
    parser = TextFileReader(fp_or_buf, **kwds)
  File "/home/airflow/.local/lib/python3.6/site-packages/pandas/io/parsers.py", line 948, in __init__
    self._make_engine(self.engine)
  File "/home/airflow/.local/lib/python3.6/site-packages/pandas/io/parsers.py", line 1180, in _make_engine
    self._engine = CParserWrapper(self.f, **self.options)
  File "/home/airflow/.local/lib/python3.6/site-packages/pandas/io/parsers.py", line 2010, in __init__
    self._reader = parsers.TextReader(src, **kwds)
  File "pandas/_libs/parsers.pyx", line 382, in pandas._libs.parsers.TextReader.__cinit__
  File "pandas/_libs/parsers.pyx", line 674, in pandas._libs.parsers.TextReader._setup_parser_source
FileNotFoundError: [Errno 2] No such file or directory: 'C:\\Users\\amey sonje\\Downloads\\csv_data.csv'
[2021-08-11 16:47:04,223] {taskinstance.py:1551} INFO - Marking task as FAILED. dag_id=pipeline_try, task_id=transform_data, execution_date=20210810T000000, start_date=20210811T164703, end_date=20210811T164704
[2021-08-11 16:47:04,318] {local_task_job.py:149} INFO - Task exited with return code 1
