[2021-08-13 08:43:24,749] {taskinstance.py:896} INFO - Dependencies all met for <TaskInstance: pipeline_try.is_today 2021-08-13T08:43:20.342682+00:00 [queued]>
[2021-08-13 08:43:24,769] {taskinstance.py:896} INFO - Dependencies all met for <TaskInstance: pipeline_try.is_today 2021-08-13T08:43:20.342682+00:00 [queued]>
[2021-08-13 08:43:24,769] {taskinstance.py:1087} INFO - 
--------------------------------------------------------------------------------
[2021-08-13 08:43:24,769] {taskinstance.py:1088} INFO - Starting attempt 1 of 2
[2021-08-13 08:43:24,770] {taskinstance.py:1089} INFO - 
--------------------------------------------------------------------------------
[2021-08-13 08:43:24,780] {taskinstance.py:1107} INFO - Executing <Task(BranchPythonOperator): is_today> on 2021-08-13T08:43:20.342682+00:00
[2021-08-13 08:43:24,786] {standard_task_runner.py:52} INFO - Started process 5713 to run task
[2021-08-13 08:43:24,790] {standard_task_runner.py:76} INFO - Running: ['***', 'tasks', 'run', 'pipeline_try', 'is_today', '2021-08-13T08:43:20.342682+00:00', '--job-id', '143', '--pool', 'default_pool', '--raw', '--subdir', 'DAGS_FOLDER/pipeline_try1.py', '--cfg-path', '/tmp/tmpkiwdw1hd', '--error-file', '/tmp/tmpa0cfv8ja']
[2021-08-13 08:43:24,794] {standard_task_runner.py:77} INFO - Job 143: Subtask is_today
[2021-08-13 08:43:24,841] {logging_mixin.py:104} INFO - Running <TaskInstance: pipeline_try.is_today 2021-08-13T08:43:20.342682+00:00 [running]> on host 99300daf4d26
[2021-08-13 08:43:24,893] {taskinstance.py:1302} INFO - Exporting the following env vars:
AIRFLOW_CTX_DAG_EMAIL=ameysonje242000@gmail.com
AIRFLOW_CTX_DAG_OWNER=amey
AIRFLOW_CTX_DAG_ID=pipeline_try
AIRFLOW_CTX_TASK_ID=is_today
AIRFLOW_CTX_EXECUTION_DATE=2021-08-13T08:43:20.342682+00:00
AIRFLOW_CTX_DAG_RUN_ID=manual__2021-08-13T08:43:20.342682+00:00
[2021-08-13 08:43:24,904] {logging_mixin.py:104} INFO - today is 4
[2021-08-13 08:43:24,905] {python.py:151} INFO - Done. Returned value was: thursday_Task
[2021-08-13 08:43:24,905] {skipmixin.py:124} INFO - Following branch thursday_Task
[2021-08-13 08:43:24,923] {taskinstance.py:1501} ERROR - Task failed with exception
Traceback (most recent call last):
  File "/home/airflow/.local/lib/python3.6/site-packages/airflow/models/taskinstance.py", line 1157, in _run_raw_task
    self._prepare_and_execute_task_with_callbacks(context, task)
  File "/home/airflow/.local/lib/python3.6/site-packages/airflow/models/taskinstance.py", line 1331, in _prepare_and_execute_task_with_callbacks
    result = self._execute_task(context, task_copy)
  File "/home/airflow/.local/lib/python3.6/site-packages/airflow/models/taskinstance.py", line 1361, in _execute_task
    result = task_copy.execute(context=context)
  File "/home/airflow/.local/lib/python3.6/site-packages/airflow/operators/python.py", line 180, in execute
    self.skip_all_except(context['ti'], branch)
  File "/home/airflow/.local/lib/python3.6/site-packages/airflow/models/skipmixin.py", line 150, in skip_all_except
    branch_task_ids.update(dag.get_task(branch_task_id).get_flat_relative_ids(upstream=False))
  File "/home/airflow/.local/lib/python3.6/site-packages/airflow/models/dag.py", line 1547, in get_task
    raise TaskNotFound(f"Task {task_id} not found")
airflow.exceptions.TaskNotFound: Task thursday_Task not found
[2021-08-13 08:43:24,931] {taskinstance.py:1551} INFO - Marking task as UP_FOR_RETRY. dag_id=pipeline_try, task_id=is_today, execution_date=20210813T084320, start_date=20210813T084324, end_date=20210813T084324
[2021-08-13 08:43:24,962] {local_task_job.py:149} INFO - Task exited with return code 1
