[2021-08-12 12:26:23,946] {taskinstance.py:896} INFO - Dependencies all met for <TaskInstance: pipeline_try.send_email 2021-08-12T12:26:13.412969+00:00 [queued]>
[2021-08-12 12:26:23,966] {taskinstance.py:896} INFO - Dependencies all met for <TaskInstance: pipeline_try.send_email 2021-08-12T12:26:13.412969+00:00 [queued]>
[2021-08-12 12:26:23,967] {taskinstance.py:1087} INFO - 
--------------------------------------------------------------------------------
[2021-08-12 12:26:23,967] {taskinstance.py:1088} INFO - Starting attempt 1 of 2
[2021-08-12 12:26:23,968] {taskinstance.py:1089} INFO - 
--------------------------------------------------------------------------------
[2021-08-12 12:26:23,982] {taskinstance.py:1107} INFO - Executing <Task(EmailOperator): send_email> on 2021-08-12T12:26:13.412969+00:00
[2021-08-12 12:26:23,987] {standard_task_runner.py:52} INFO - Started process 13543 to run task
[2021-08-12 12:26:23,992] {standard_task_runner.py:76} INFO - Running: ['***', 'tasks', 'run', 'pipeline_try', 'send_email', '2021-08-12T12:26:13.412969+00:00', '--job-id', '78', '--pool', 'default_pool', '--raw', '--subdir', 'DAGS_FOLDER/pipeline_try1.py', '--cfg-path', '/tmp/tmpemk15t7o', '--error-file', '/tmp/tmpvyyvjwp0']
[2021-08-12 12:26:23,999] {standard_task_runner.py:77} INFO - Job 78: Subtask send_email
[2021-08-12 12:26:24,055] {logging_mixin.py:104} INFO - Running <TaskInstance: pipeline_try.send_email 2021-08-12T12:26:13.412969+00:00 [running]> on host 99300daf4d26
[2021-08-12 12:26:24,130] {taskinstance.py:1302} INFO - Exporting the following env vars:
AIRFLOW_CTX_DAG_EMAIL=ameysonje242000@gmail.com
AIRFLOW_CTX_DAG_OWNER=amey
AIRFLOW_CTX_DAG_ID=pipeline_try
AIRFLOW_CTX_TASK_ID=send_email
AIRFLOW_CTX_EXECUTION_DATE=2021-08-12T12:26:13.412969+00:00
AIRFLOW_CTX_DAG_RUN_ID=manual__2021-08-12T12:26:13.412969+00:00
[2021-08-12 12:26:24,216] {logging_mixin.py:104} WARNING - /home/***/.local/lib/python3.6/site-packages/***/utils/email.py:102 PendingDeprecationWarning: Fetching SMTP credentials from configuration variables will be deprecated in a future release. Please set credentials using a connection instead.
[2021-08-12 12:26:24,217] {configuration.py:365} WARNING - section/key [smtp/smtp_user] not found in config
[2021-08-12 12:26:24,217] {email.py:208} INFO - Email alerting: attempt 1
[2021-08-12 12:26:24,219] {taskinstance.py:1501} ERROR - Task failed with exception
Traceback (most recent call last):
  File "/home/airflow/.local/lib/python3.6/site-packages/airflow/models/taskinstance.py", line 1157, in _run_raw_task
    self._prepare_and_execute_task_with_callbacks(context, task)
  File "/home/airflow/.local/lib/python3.6/site-packages/airflow/models/taskinstance.py", line 1331, in _prepare_and_execute_task_with_callbacks
    result = self._execute_task(context, task_copy)
  File "/home/airflow/.local/lib/python3.6/site-packages/airflow/models/taskinstance.py", line 1361, in _execute_task
    result = task_copy.execute(context=context)
  File "/home/airflow/.local/lib/python3.6/site-packages/airflow/operators/email.py", line 88, in execute
    conn_id=self.conn_id,
  File "/home/airflow/.local/lib/python3.6/site-packages/airflow/utils/email.py", line 66, in send_email
    **kwargs,
  File "/home/airflow/.local/lib/python3.6/site-packages/airflow/utils/email.py", line 102, in send_email_smtp
    send_mime_email(e_from=smtp_mail_from, e_to=recipients, mime_msg=msg, conn_id=conn_id, dryrun=dryrun)
  File "/home/airflow/.local/lib/python3.6/site-packages/airflow/utils/email.py", line 210, in send_mime_email
    conn = _get_smtp_connection(smtp_host, smtp_port, smtp_timeout, smtp_ssl)
  File "/home/airflow/.local/lib/python3.6/site-packages/airflow/utils/email.py", line 244, in _get_smtp_connection
    else smtplib.SMTP(host=host, port=port, timeout=timeout)
  File "/usr/local/lib/python3.6/smtplib.py", line 251, in __init__
    (code, msg) = self.connect(host, port)
  File "/usr/local/lib/python3.6/smtplib.py", line 336, in connect
    self.sock = self._get_socket(host, port, self.timeout)
  File "/usr/local/lib/python3.6/smtplib.py", line 307, in _get_socket
    self.source_address)
  File "/usr/local/lib/python3.6/socket.py", line 724, in create_connection
    raise err
  File "/usr/local/lib/python3.6/socket.py", line 713, in create_connection
    sock.connect(sa)
OSError: [Errno 99] Cannot assign requested address
[2021-08-12 12:26:24,222] {taskinstance.py:1551} INFO - Marking task as UP_FOR_RETRY. dag_id=pipeline_try, task_id=send_email, execution_date=20210812T122613, start_date=20210812T122623, end_date=20210812T122624
[2021-08-12 12:26:24,286] {local_task_job.py:149} INFO - Task exited with return code 1
