[2021-08-13 07:05:58,986] {taskinstance.py:896} INFO - Dependencies all met for <TaskInstance: pipeline_try.httpgettry 2021-08-12T00:00:00+00:00 [queued]>
[2021-08-13 07:05:59,010] {taskinstance.py:896} INFO - Dependencies all met for <TaskInstance: pipeline_try.httpgettry 2021-08-12T00:00:00+00:00 [queued]>
[2021-08-13 07:05:59,011] {taskinstance.py:1087} INFO - 
--------------------------------------------------------------------------------
[2021-08-13 07:05:59,011] {taskinstance.py:1088} INFO - Starting attempt 2 of 2
[2021-08-13 07:05:59,012] {taskinstance.py:1089} INFO - 
--------------------------------------------------------------------------------
[2021-08-13 07:05:59,025] {taskinstance.py:1107} INFO - Executing <Task(SimpleHttpOperator): httpgettry> on 2021-08-12T00:00:00+00:00
[2021-08-13 07:05:59,032] {standard_task_runner.py:52} INFO - Started process 2366 to run task
[2021-08-13 07:05:59,039] {standard_task_runner.py:76} INFO - Running: ['***', 'tasks', 'run', 'pipeline_try', 'httpgettry', '2021-08-12T00:00:00+00:00', '--job-id', '140', '--pool', 'default_pool', '--raw', '--subdir', 'DAGS_FOLDER/pipeline_try1.py', '--cfg-path', '/tmp/tmp3xkfe1tw', '--error-file', '/tmp/tmptzr8ihck']
[2021-08-13 07:05:59,044] {standard_task_runner.py:77} INFO - Job 140: Subtask httpgettry
[2021-08-13 07:05:59,119] {logging_mixin.py:104} INFO - Running <TaskInstance: pipeline_try.httpgettry 2021-08-12T00:00:00+00:00 [running]> on host 99300daf4d26
[2021-08-13 07:05:59,202] {taskinstance.py:1302} INFO - Exporting the following env vars:
AIRFLOW_CTX_DAG_EMAIL=ameysonje242000@gmail.com
AIRFLOW_CTX_DAG_OWNER=amey
AIRFLOW_CTX_DAG_ID=pipeline_try
AIRFLOW_CTX_TASK_ID=httpgettry
AIRFLOW_CTX_EXECUTION_DATE=2021-08-12T00:00:00+00:00
AIRFLOW_CTX_DAG_RUN_ID=scheduled__2021-08-12T00:00:00+00:00
[2021-08-13 07:05:59,205] {http.py:111} INFO - Calling HTTP method
[2021-08-13 07:05:59,225] {base.py:78} INFO - Using connection to: id: http_post. Host: 172.18.16.1, Port: 8000, Schema: , Login: , Password: None, extra: {}
[2021-08-13 07:05:59,229] {http.py:140} INFO - Sending 'GET' to url: http://172.18.16.1:8000/Users/
[2021-08-13 07:06:20,276] {http.py:202} WARNING - HTTPConnectionPool(host='172.18.16.1', port=8000): Max retries exceeded with url: /Users/?user_id=amey_sonje (Caused by NewConnectionError('<urllib3.connection.HTTPConnection object at 0x7ff39ee8b400>: Failed to establish a new connection: [Errno 111] Connection refused',)) Tenacity will retry to execute the operation
[2021-08-13 07:06:20,281] {taskinstance.py:1501} ERROR - Task failed with exception
Traceback (most recent call last):
  File "/home/airflow/.local/lib/python3.6/site-packages/urllib3/connection.py", line 160, in _new_conn
    (self._dns_host, self.port), self.timeout, **extra_kw
  File "/home/airflow/.local/lib/python3.6/site-packages/urllib3/util/connection.py", line 84, in create_connection
    raise err
  File "/home/airflow/.local/lib/python3.6/site-packages/urllib3/util/connection.py", line 74, in create_connection
    sock.connect(sa)
ConnectionRefusedError: [Errno 111] Connection refused

During handling of the above exception, another exception occurred:

Traceback (most recent call last):
  File "/home/airflow/.local/lib/python3.6/site-packages/urllib3/connectionpool.py", line 677, in urlopen
    chunked=chunked,
  File "/home/airflow/.local/lib/python3.6/site-packages/urllib3/connectionpool.py", line 392, in _make_request
    conn.request(method, url, **httplib_request_kw)
  File "/usr/local/lib/python3.6/http/client.py", line 1287, in request
    self._send_request(method, url, body, headers, encode_chunked)
  File "/usr/local/lib/python3.6/http/client.py", line 1333, in _send_request
    self.endheaders(body, encode_chunked=encode_chunked)
  File "/usr/local/lib/python3.6/http/client.py", line 1282, in endheaders
    self._send_output(message_body, encode_chunked=encode_chunked)
  File "/usr/local/lib/python3.6/http/client.py", line 1042, in _send_output
    self.send(msg)
  File "/usr/local/lib/python3.6/http/client.py", line 980, in send
    self.connect()
  File "/home/airflow/.local/lib/python3.6/site-packages/urllib3/connection.py", line 187, in connect
    conn = self._new_conn()
  File "/home/airflow/.local/lib/python3.6/site-packages/urllib3/connection.py", line 172, in _new_conn
    self, "Failed to establish a new connection: %s" % e
urllib3.exceptions.NewConnectionError: <urllib3.connection.HTTPConnection object at 0x7ff39ee8b400>: Failed to establish a new connection: [Errno 111] Connection refused

During handling of the above exception, another exception occurred:

Traceback (most recent call last):
  File "/home/airflow/.local/lib/python3.6/site-packages/requests/adapters.py", line 449, in send
    timeout=timeout
  File "/home/airflow/.local/lib/python3.6/site-packages/urllib3/connectionpool.py", line 727, in urlopen
    method, url, error=e, _pool=self, _stacktrace=sys.exc_info()[2]
  File "/home/airflow/.local/lib/python3.6/site-packages/urllib3/util/retry.py", line 446, in increment
    raise MaxRetryError(_pool, url, error or ResponseError(cause))
urllib3.exceptions.MaxRetryError: HTTPConnectionPool(host='172.18.16.1', port=8000): Max retries exceeded with url: /Users/?user_id=amey_sonje (Caused by NewConnectionError('<urllib3.connection.HTTPConnection object at 0x7ff39ee8b400>: Failed to establish a new connection: [Errno 111] Connection refused',))

During handling of the above exception, another exception occurred:

Traceback (most recent call last):
  File "/home/airflow/.local/lib/python3.6/site-packages/airflow/models/taskinstance.py", line 1157, in _run_raw_task
    self._prepare_and_execute_task_with_callbacks(context, task)
  File "/home/airflow/.local/lib/python3.6/site-packages/airflow/models/taskinstance.py", line 1331, in _prepare_and_execute_task_with_callbacks
    result = self._execute_task(context, task_copy)
  File "/home/airflow/.local/lib/python3.6/site-packages/airflow/models/taskinstance.py", line 1361, in _execute_task
    result = task_copy.execute(context=context)
  File "/home/airflow/.local/lib/python3.6/site-packages/airflow/providers/http/operators/http.py", line 113, in execute
    response = http.run(self.endpoint, self.data, self.headers, self.extra_options)
  File "/home/airflow/.local/lib/python3.6/site-packages/airflow/providers/http/hooks/http.py", line 141, in run
    return self.run_and_check(session, prepped_request, extra_options)
  File "/home/airflow/.local/lib/python3.6/site-packages/airflow/providers/http/hooks/http.py", line 203, in run_and_check
    raise ex
  File "/home/airflow/.local/lib/python3.6/site-packages/airflow/providers/http/hooks/http.py", line 195, in run_and_check
    response = session.send(prepped_request, **send_kwargs)
  File "/home/airflow/.local/lib/python3.6/site-packages/requests/sessions.py", line 655, in send
    r = adapter.send(request, **kwargs)
  File "/home/airflow/.local/lib/python3.6/site-packages/requests/adapters.py", line 516, in send
    raise ConnectionError(e, request=request)
requests.exceptions.ConnectionError: HTTPConnectionPool(host='172.18.16.1', port=8000): Max retries exceeded with url: /Users/?user_id=amey_sonje (Caused by NewConnectionError('<urllib3.connection.HTTPConnection object at 0x7ff39ee8b400>: Failed to establish a new connection: [Errno 111] Connection refused',))
[2021-08-13 07:06:20,289] {taskinstance.py:1551} INFO - Marking task as FAILED. dag_id=pipeline_try, task_id=httpgettry, execution_date=20210812T000000, start_date=20210813T070558, end_date=20210813T070620
[2021-08-13 07:06:20,340] {local_task_job.py:149} INFO - Task exited with return code 1
